<?xml version="1.0" encoding="utf-8"?>
<robot name="dofbot">
  <ros2_control name="dofbot_robot" type="actuator">
    <hardware>
      <plugin>dofbot::DofbotServo</plugin>
      <param name="mode">hardware</param>
    </hardware>
    <joint name="joint1">
      <command_interface name="position">
        <param name="min">-1.57</param>
        <param name="max">1.57</param>
      </command_interface>
      <state_interface name="position" />
    </joint>
    <joint name="joint2">
      <command_interface name="position">
        <param name="min">-1.57</param>
        <param name="max">1.57</param>
      </command_interface>
      <state_interface name="position" />
    </joint>
    <joint name="joint3">
      <command_interface name="position">
        <param name="min">-1.57</param>
        <param name="max">1.57</param>
      </command_interface>
      <state_interface name="position" />
    </joint>
    <joint name="joint4">
      <command_interface name="position">
        <param name="min">-1.57</param>
        <param name="max">1.57</param>
      </command_interface>
      <state_interface name="position" />
    </joint>
    <joint name="joint5">
      <command_interface name="position">
        <param name="min">-1.57</param>
        <param name="max">3.1416</param>
      </command_interface>
      <state_interface name="position" />
    </joint>
    <joint name="gripper">
      <command_interface name="position">
        <param name="min">-1.57</param>
        <param name="max">3.1416</param>
      </command_interface>
      <state_interface name="position" />
    </joint>
    </ros2_control>
  <link name="world" />
	<joint name="virtual_joint" type="fixed">
		<parent link="world"/>
		<child link="base_link"/>
		<origin xyz= "0 0 0" rpy = "0 0 0"/>  
	</joint>
  <link name="base_link">
    <visual>
      <origin xyz="0 0 0" rpy="0 0 0" />
      <geometry>
        <mesh filename="package://dofbot/meshes/base_link.STL" />
      </geometry>
      <material name="">
        <color rgba="0.7 0.7 0.7 1" />
      </material>
    </visual>
    <collision>
      <origin xyz="0 0 0" rpy="0 0 0" />
      <geometry>
        <mesh filename="package://dofbot/meshes/base_link.STL" />
      </geometry>
    </collision>
  </link>
  <link name="link1">
    <visual>
      <origin xyz="0 0 0" rpy="0 0 0" />
      <geometry>
        <mesh filename="package://dofbot/meshes/link1.STL" />
      </geometry>
      <material name="">
        <color rgba="0 0.7 0 1" />
      </material>
    </visual>
    <collision>
      <origin xyz="0 0 0" rpy="0 0 0" />
      <geometry>
        <mesh filename="package://dofbot/meshes/link1.STL" />
      </geometry>
    </collision>
  </link>
  <joint name="joint1" type="revolute">
    <origin xyz="0 0 0.064" rpy="0 0 0" />
    <parent link="base_link" />
    <child link="link1" />
    <axis xyz="0 0 1" />
    <limit acceleration="4" lower="-1.5708" upper="1.5708" effort="100"
    velocity="1" />
  </joint>
  <link name="link2">
    <visual>
      <origin xyz="0 0 0" rpy="0 0 0" />
      <geometry>
        <mesh filename="package://dofbot/meshes/link2.STL" />
      </geometry>
      <material name="">
        <color rgba="0.7 0.7 0.7 1" />
      </material>
    </visual>
    <collision>
      <origin xyz="0 0 0" rpy="0 0 0" />
      <geometry>
        <mesh filename="package://dofbot/meshes/link2.STL" />
      </geometry>
    </collision>
  </link>
  <joint name="joint2" type="revolute">
    <origin xyz="0 0 0.0435" rpy="0 1.5708 0" />
    <parent link="link1" />
    <child link="link2" />
    <axis xyz="0 0 1" />
    <limit acceleration="4" lower="-1.5708" upper="1.5708" effort="100"
    velocity="1" />
  </joint>
  <link name="link3">
    <visual>
      <origin xyz="0 0 0" rpy="0 0 0" />
      <geometry>
        <mesh filename="package://dofbot/meshes/link3.STL" />
      </geometry>
      <material name="">
        <color rgba="0 0.7 0 1" />
      </material>
    </visual>
    <collision>
      <origin xyz="0 0 0" rpy="0 0 0" />
      <geometry>
        <mesh filename="package://dofbot/meshes/link3.STL" />
      </geometry>
    </collision>
  </link>
  <joint name="joint3" type="revolute">
    <origin xyz="-0.08285 0 0" rpy="0 0 0" />
    <parent link="link2" />
    <child link="link3" />
    <axis xyz="0 0 1" />
    <limit acceleration="4" lower="-1.5708" upper="1.5708" effort="100"
    velocity="1" />
  </joint>
  <link name="link4">
    <visual>
      <origin xyz="0 0 0" rpy="0 0 0" />
      <geometry>
        <mesh filename="package://dofbot/meshes/link4.STL" />
      </geometry>
      <material name="">
        <color rgba="0.7 0.7 0.7 1" />
      </material>
    </visual>
    <collision>
      <origin xyz="0 0 0" rpy="0 0 0" />
      <geometry>
        <mesh filename="package://dofbot/meshes/link4.STL" />
      </geometry>
    </collision>
  </link>
  <joint name="joint4" type="revolute">
    <origin xyz="-0.08285 0 0" rpy="0 0 0" />
    <parent link="link3" />
    <child link="link4" />
    <axis xyz="0 0 1" />
    <limit acceleration="4" lower="-1.5708" upper="1.5708" effort="100"
    velocity="1" />
  </joint>
  <link name="link5">
    <visual>
      <origin xyz="0 0 0" rpy="0 0 0" />
      <geometry>
        <mesh filename="package://dofbot/meshes/link5-nofinger.stl" />
      </geometry>
      <material name="">
        <color rgba="1 1 1 1" />
      </material>
    </visual>
    <collision>
      <origin xyz="0 0 0" rpy="0 0 0" />
      <geometry>
        <mesh filename="package://dofbot/meshes/link5-nofinger.stl" />
      </geometry>
    </collision>
  </link>
  <joint name="joint5" type="revolute">
    <origin xyz="-0.07385 -0.00215 0" rpy="0 -1.5708 0" />
    <parent link="link4" />
    <child link="link5" />
    <axis xyz="0 0 1" />
    <limit acceleration="4" lower="-1.5708" upper="3.1416" effort="100"
    velocity="1" />
  </joint>
  <link name="left_finger">
    <visual>
      <origin xyz="0 0 0" rpy="0 0 0" />
      <geometry>
        <mesh filename="package://dofbot/meshes/leftfinger.stl" />
      </geometry>
      <material name="">
        <color rgba="1 1 1 1" />
      </material>
    </visual>
    <collision>
      <origin xyz="0 0 0" rpy="0 0 0" />
      <geometry>
        <mesh filename="package://dofbot/meshes/leftfinger.stl" />
      </geometry>
    </collision>
  </link>
  <link name="right_finger">
    <visual>
      <origin xyz="0 0 0" rpy="0 0 0" />
      <geometry>
        <mesh filename="package://dofbot/meshes/rightfinger.stl" />
      </geometry>
      <material name="">
        <color rgba="1 1 1 1" />
      </material>
    </visual>
    <collision>
      <origin xyz="0 0 0" rpy="0 0 0" />
      <geometry>
        <mesh filename="package://dofbot/meshes/rightfinger.stl" />
      </geometry>
    </collision>
  </link>
  <joint name="gripper" type="prismatic">
    <origin xyz="0 0 0" rpy="0 0 0" />
    <parent link="link5" />
    <child link="left_finger" />
    <axis xyz="1 0 0" />
    <limit acceleration="4" lower="-0.03" upper="0.05" effort="100" velocity="1" />
  </joint>
  <joint name="gripper_right" type="prismatic">
    <origin xyz="0 0 0" rpy="0 0 0" />
    <parent link="left_finger" />
    <child link="right_finger" />
    <axis xyz="1 0 0" />
    <limit acceleration="4" lower="-0.03" upper="0.05" effort="100" velocity="1" />
  </joint>
</robot>
